Workbook

Sheet AccountDağılımı 2026
A1: 2025-4 Satış Yöneticisi | B1: 2026-1 Satış Yöneticisi | C1: Proje | D1: 2025 Yeni Satış TL | E1: 2025 Yenileme TL | F1: 2026 HEDEF Yeni Satış | G1: 2026 HEDEF Yenileme TL | H1: Durum | I1: Sınıf | J1: Sınıf-2 | K1: Müşteri | L1: Ana Sektör | M1: Alt Sektör | N1: BFH Fırsatına göre | O1: Komplex İhtiyaçları Var mı? | P1: Şehir | Q1: Ürünler | R1: Risk Var mı?
A2: Begüm Hayta | B2: Begüm Hayta | C2: ABC Deterjan | D2: 2658550 | F2: =D2*(1+56%) -> 4147338 | G2: =E2*(1+56%) -> 0 | H2: Yeni | I2: 3 | J2: 3 | K2: ABC Deterjan | L2: FMCG | M2: Temizlik Deterjan | N2: Var | O2: Hayır | P2: İstanbul | Q2: Enroute | R2: Hayır
A3: Semih Balaban | B3: Begüm Hayta | C3: ALPEDO | D3: 5150520 | E3: 1116214.9 | F3: =D3*(1+56%) -> 8034811.2 | G3: =E3*(1+56%) -> 1741295.2 | H3: Aktif | I3: 3 | J3: 3 | K3: ALPEDO | L3: FMCG | M3: Gıda | N3: Var | O3: Hayır | P3: Kahramanmaraş | Q3: Enroute | R3: Hayır
A4: Nigar Uygun | B4: Begüm Hayta | C4: ALTIPARMAK-BALPARMAK | D4: 0 | E4: 1769359.7 | F4: =D4*(1+56%) -> 0 | G4: =E4*(1+56%) -> 2760201.1 | H4: Aktif | I4: 3 | J4: 3 | K4: ALTIPARMAK-BALPARMAK | L4: FMCG | M4: Gıda | N4: Var | O4: Hayır | P4: İstanbul | Q4: Enroute | R4: Hayır
A5: Begüm Hayta | B5: Begüm Hayta | C5: ÇAYKUR | D5: 1678630 | E5: 2533873.3 | F5: =D5*(1+56%) -> 2618662.8 | G5: =E5*(1+56%) -> 3952842.4 | H5: Aktif | I5: 2 | J5: 2 | K5: ÇAYKUR | L5: FMCG | M5: Çay | N5: Var | O5: Hayır | P5: Rize | Q5: Eroute, Stokbar | R5: Hayır
A6: Onur Günay | B6: Begüm Hayta | C6: DANONE TIKVESLI | D6: 105352.91 | E6: 2174000 | F6: =D6*(1+56%) -> 164350.54 | G6: =E6*(1+56%) -> 3391440 | H6: Sonlanıyor | I6: Key Account | J6: Key Account | K6: DANONE | L6: FMCG | M6: Gıda | N6: Yok | O6: Hayır | P6: İstanbul | Q6: Enroute | R6: Sonlandı
A7: Onur Günay | B7: Begüm Hayta | C7: DANONE WATERS | D7: 0 | E7: 2016738.3 | F7: =D7*(1+56%) -> 0 | G7: =E7*(1+56%) -> 3146111.7 | H7: Sonlanıyor | I7: Key Account | J7: Key Account | K7: DANONE | L7: FMCG | M7: Gıda | N7: Yok | O7: Hayır | P7: İstanbul | Q7: Enroute | R7: Sonlandı
A8: Begüm Hayta | B8: Begüm Hayta | C8: DARDANEL | D8: 156215 | E8: 2709095.9 | F8: =D8*(1+56%) -> 243695.4 | G8: =E8*(1+56%) -> 4226189.7 | H8: Aktif | I8: 2 | J8: 2 | K8: DARDANEL | L8: FMCG | M8: Gıda | N8: Var | O8: Evet | P8: İstanbul | Q8: Enroute | R8: Hayır
A9: Nigar Uygun | B9: Begüm Hayta | C9: DOGADAN | D9: 12250 | E9: 259285 | F9: =D9*(1+56%) -> 19110 | G9: =E9*(1+56%) -> 404484.6 | H9: Aktif | I9: 3 | J9: 3 | K9: DOGADAN | L9: FMCG | M9: Çay | N9: Yok | O9: Hayır | P9: İstanbul | Q9: Quest | R9: Evet
A10: Begüm Hayta | B10: Begüm Hayta | C10: DOGUS CAY | D10: 6828520 | E10: =2945269.38+7644633 -> 10589902 | F10: =D10*(1+56%) -> 10652491 | G10: =E10*(1+56%) -> 16520248 | H10: Aktif | I10: 2 | J10: Key Account | K10: DOGUS CAY | L10: FMCG | M10: Çay | N10: Var | O10: Hayır | P10: İstanbul | Q10: Enroute, Quest, Stokbar | R10: Hayır
A11: Mülkiye Akdoğaner | B11: Begüm Hayta | C11: HARIBO | D11: 1372187.8 | E11: 4496625.1 | F11: =D11*(1+56%) -> 2140612.9 | G11: =E11*(1+56%) -> 7014735.1 | H11: Aktif | I11: 3 | J11: Key Account | K11: HARIBO | L11: FMCG | M11: Atıştırmalık | N11: Var | O11: Hayır | P11: İstanbul | Q11: Enroute | R11: Hayır
A12: Begüm Hayta | B12: Begüm Hayta | C12: KENT GIDA | D12: 8939309.2 | E12: 3586227.2 | F12: =D12*(1+56%) -> 13945322 | G12: =E12*(1+56%) -> 5594514.4 | H12: Aktif | I12: Key Account | J12: Key Account | K12: KENT GIDA | L12: FMCG | M12: Atıştırmalık | N12: Var | O12: Evet | P12: İstanbul | Q12: Eroute, Stokbar | R12: Hayır
A13: Mülkiye Akdoğaner | B13: Begüm Hayta | C13: LA LORRAINE | D13: 411951.43 | E13: 2829212.7 | F13: =D13*(1+56%) -> 642644.23 | G13: =E13*(1+56%) -> 4413571.9 | H13: Aktif | I13: 3 | J13: 3 | K13: LA LORRAINE | L13: FMCG | M13: Gıda | N13: Var | O13: Hayır | P13: İstanbul | Q13: Enroute | R13: Hayır
A14: Begüm Hayta | B14: Begüm Hayta | C14: MARS GIDA | E14: 3326577.1 | F14: =D14*(1+56%) -> 0 | G14: =E14*(1+56%) -> 5189460.3 | H14: Aktif | I14: 2 | J14: 2 | K14: MARS GIDA | L14: FMCG | M14: Atıştırmalık | N14: Var | O14: Hayır | P14: İstanbul | Q14: Enroute | R14: Hayır
A15: Begüm Hayta | B15: Begüm Hayta | C15: NESTLE PROFESIONAL | D15: 631665.75 | E15: 2627689.6 | F15: =D15*(1+56%) -> 985398.57 | G15: =E15*(1+56%) -> 4099195.8 | H15: Aktif | I15: 1 | J15: Key Account | K15: NESTLE | L15: FMCG | M15: Atıştırmalık | N15: Var | O15: Evet | P15: İstanbul | Q15: Enroute, Quest | R15: Hayır
A16: Begüm Hayta | B16: Begüm Hayta | C16: NESTLE RETAIL | D16: 1424156.2 | E16: 6731205 | F16: =D16*(1+56%) -> 2221683.6 | G16: =E16*(1+56%) -> 10500680 | H16: Aktif | I16: Key Account | J16: Key Account | K16: NESTLE | L16: FMCG | M16: Atıştırmalık | N16: Var | O16: Evet | P16: İstanbul | Q16: Enroute, Quest | R16: Evet
A17: Begüm Hayta | B17: Begüm Hayta | C17: NESTLE ROM | D17: 232172.85 | E17: 518720.73 | F17: =D17*(1+56%) -> 362189.65 | G17: =E17*(1+56%) -> 809204.34 | H17: Aktif | I17: Key Account | J17: Key Account | K17: NESTLE | L17: FMCG | M17: Atıştırmalık | N17: Var | O17: Evet | P17: İstanbul | Q17: Enroute, Quest | R17: Hayır
A18: Begüm Hayta | B18: Begüm Hayta | C18: NESTLE WATERS | D18: 171500 | E18: 518720.73 | F18: =D18*(1+56%) -> 267540 | G18: =E18*(1+56%) -> 809204.34 | H18: Aktif | I18: 1 | J18: Key Account | K18: NESTLE | L18: FMCG | M18: Atıştırmalık | N18: Var | O18: Evet | P18: İstanbul | Q18: Enroute, Quest | R18: Hayır
A19: Begüm Hayta | B19: Begüm Hayta | C19: NESTLE STARBUCKS | D19: 293200.89 | E19: 3284980.9 | F19: =D19*(1+56%) -> 457393.39 | G19: =E19*(1+56%) -> 5124570.3 | H19: Aktif | I19: 1 | J19: Key Account | K19: NESTLE | L19: FMCG | M19: Atıştırmalık | N19: Var | O19: Evet | P19: İstanbul | Q19: Stokbar | R19: Hayır
A20: Semih Balaban | B20: Begüm Hayta | C20: OFÇAY - EFOR ÇAY | E20: 1041939.7 | F20: =D20*(1+56%) -> 0 | G20: =E20*(1+56%) -> 1625425.9 | H20: Aktif | I20: 3 | J20: 3 | K20: OFÇAY - EFOR ÇAY | L20: FMCG | M20: Çay | N20: Var | O20: Hayır | P20: İstanbul | Q20: Enroute | R20: Hayır
A21: Semih Balaban | B21: Begüm Hayta | C21: ÖZGÖRKEY | D21: 254340.05 | E21: 1059355.2 | F21: =D21*(1+56%) -> 396770.48 | G21: =E21*(1+56%) -> 1652594.1 | H21: Aktif | I21: 3 | J21: 3 | K21: ÖZGÖRKEY | L21: FMCG | M21: Gıda | N21: Var | O21: Hayır | P21: İzmir | Q21: Eroute, Stokbar | R21: Hayır
A22: Semih Balaban | B22: Begüm Hayta | C22: SEN PILIC | D22: 1325245 | E22: 3600551.5 | F22: =D22*(1+56%) -> 2067382.2 | G22: =E22*(1+56%) -> 5616860.4 | H22: Aktif | I22: 2 | J22: Key Account | K22: SEN PILIC | L22: FMCG | M22: Gıda | N22: Var | O22: Hayır | P22: İstanbul | Q22: Enroute | R22: Hayır
A23: Semih Balaban | B23: Begüm Hayta | C23: SÖLEN | D23: 2017419.6 | E23: 2000000 | F23: =D23*(1+56%) -> 3147174.6 | G23: =E23*(1+56%) -> 3120000 | H23: Aktif | I23: Key Account | J23: Key Account | K23: SÖLEN | L23: FMCG | M23: Atıştırmalık | N23: Var | O23: Hayır | P23: İstanbul | Q23: Enroute | R23: Hayır
A24: Onur Günay | B24: Begüm Hayta | C24: SÖLEN IRAK | D24: 0 | E24: 0 | F24: =D24*(1+56%) -> 0 | G24: =E24*(1+56%) -> 0 | H24: Aktif | I24: Key Account | J24: Key Account | K24: SÖLEN IRAK | L24: FMCG | M24: Atıştırmalık | N24: Var | O24: Hayır | P24: İstanbul | Q24: Enroute | R24: Hayır
A25: Mülkiye Akdoğaner | B25: Begüm Hayta | C25: MAGNUM AŞ | F25: =D25*(1+56%) -> 0 | G25: =E25*(1+56%) -> 0 | H25: Aktif | I25: Key Account | J25: Key Account | K25: MAGNUM AŞ | L25: FMCG | M25: Atıştırmalık | N25: Var | O25: Hayır | P25: İstanbul | Q25: Stokbar | R25: Hayır
A26: BFG | B26: BFG | C26: BFG | D26: 4980743 | F26: =D26*(1+230%) -> 16436452 | H26: Aktif | K26: BFG | L26: BFG | M26: BFG | N26: Var | Q26: BFG
A27: Param Grup | B27: Dilara Bogu | C27: Grup Şirketleri | D27: 5820315 | G27: =D27*(1+30%) -> 7566409.5 | H27: Aktif | K27: Grup Şirketleri | L27: Grup Şirketleri | M27: Grup Şirketleri
A28: E-Dönüşüm | B28: E-Dönüşüm | C28: E-Dönüşüm | D28: 25326464 | F28: =D28*(1+200%) -> 75979392 | H28: Aktif | K28: E-Dönüşüm | L28: E-Dönüşüm | M28: E-Dönüşüm | N28: Var | Q28: E-Dönüşüm
A29: Semih Balaban | B29: İptal | C29: ANA GIDA- BUNGE GIDA | D29: 0 | E29: 0 | F29: =D29*(1+56%) -> 0 | G29: =E29*(1+56%) -> 0 | H29: Sonlandı | I29: 3 | J29: 3 | K29: ANA GIDA- BUNGE GIDA | L29: FMCG | M29: Gıda | N29: Yok | O29: Hayır | P29: İstanbul | Q29: Enroute, Quest | R29: Sonlandı
A30: Semih Balaban | B30: İptal | C30: AROMA | D30: 0 | E30: 0 | F30: =D30*(1+56%) -> 0 | G30: =E30*(1+56%) -> 0 | H30: Hold | I30: 3 | J30: 3 | K30: AROMA | L30: FMCG | M30: İçecek | N30: Yok | O30: Hayır | P30: Bursa | Q30: Enroute | R30: Sonlandı
A31: Nigar Uygun | B31: İptal | C31: AZTEK | D31: 0 | E31: 0 | F31: =D31*(1+56%) -> 0 | G31: =E31*(1+56%) -> 0 | H31: Sonlandı | I31: 4 | J31: 4 | K31: AZTEK | L31: Sağlık | M31: Tıbbi Malzeme | N31: Yok | O31: Hayır | P31: İstanbul | Q31: Stokbar | R31: Sonlandı
A32: Mülkiye Akdoğaner | B32: İptal | C32: DOGANAY | D32: 0 | E32: 1850243.7 | F32: =D32*(1+56%) -> 0 | G32: =E32*(1+56%) -> 2886380.2 | H32: Sonlandı | I32: 3 | J32: 3 | K32: DOGANAY | L32: FMCG | M32: Çay | N32: Yok | O32: Hayır | P32: İstanbul | Q32: Enroute | R32: Sonlandı
A33: Mülkiye Akdoğaner | B33: İptal | C33: DOĞAN TREND | D33: 2691515 | E33: 2569397.5 | F33: =D33*(1+56%) -> 4198763.5 | G33: =E33*(1+56%) -> 4008260.1 | H33: Sonlandı | I33: Key Account | J33: Key Account | K33: DOĞAN TREND | L33: Otomotiv | M33: Distribütör | N33: Yok | O33: Hayır | P33: İstanbul | Q33: Calldesk, Enroute | R33: Sonlandı
A34: Onur Günay | B34: İptal | C34: EFES AZERBAYCAN | D34: 0 | E34: 0 | F34: =D34*(1+56%) -> 0 | G34: =E34*(1+56%) -> 0 | H34: Sonlandı | I34: 1 | J34: 1 | K34: EFES AZERBAYCAN | L34: FMCG | M34: Alkol | N34: Yok | O34: Hayır | P34: Yurtdışı | Q34: Enroute | R34: Sonlandı
A35: Semih Balaban | B35: İptal | C35: EFES BELARUS | D35: 0 | E35: 355656.33 | F35: =D35*(1+56%) -> 0 | G35: =E35*(1+56%) -> 554823.88 | H35: Sonlandı | I35: 1 | J35: 1 | K35: EFES BELARUS | L35: FMCG | M35: Alkol | N35: Yok | O35: Hayır | P35: Yurtdışı | Q35: Enroute | R35: Sonlandı
A36: Onur Günay | B36: İptal | C36: EFES KIBRIS | D36: 0 | E36: 0 | F36: =D36*(1+56%) -> 0 | G36: =E36*(1+56%) -> 0 | H36: Sonlandı | I36: 4 | J36: 4 | K36: EFES KIBRIS | L36: FMCG | M36: Alkol | N36: Yok | O36: Hayır | P36: Yurtdışı | Q36: Enroute | R36: Sonlandı
A37: Onur Günay | B37: İptal | C37: EFES TÜRKIYE | D37: 67600 | E37: 0 | F37: =D37*(1+56%) -> 105456 | G37: =E37*(1+56%) -> 0 | H37: Sonlandı | I37: 1 | J37: 1 | K37: EFES TÜRKIYE | L37: FMCG | M37: Alkol | N37: Yok | O37: Hayır | P37: İstanbul | Q37: Enroute | R37: Sonlandı
A38: Mülkiye Akdoğaner | B38: İptal | C38: EGETAV | D38: 0 | E38: 0 | F38: =D38*(1+56%) -> 0 | G38: =E38*(1+56%) -> 0 | H38: Sonlandı | I38: 4 | J38: 4 | K38: EGETAV | L38: Havacılık | M38: Yer Hizmetleri | N38: Yok | O38: Hayır | P38: İstanbul | Q38: Stokbar | R38: Sonlandı
A39: Begüm Hayta | B39: İptal | C39: ENERJISA | D39: 0 | E39: 262535.18 | F39: =D39*(1+56%) -> 0 | G39: =E39*(1+56%) -> 409554.88 | H39: Sonlandı | I39: 3 | J39: 3 | K39: ENERJISA | L39: Enerji | M39: Enerji | N39: Yok | O39: Hayır | P39: İstanbul | Q39: Quest | R39: Sonlandı
A40: Onur Günay | B40: İptal | C40: HENKEL | D40: 28000 | E40: 2179129.7 | F40: =D40*(1+56%) -> 43680 | G40: =E40*(1+56%) -> 3399442.3 | H40: Sonlandı | I40: 2 | J40: 2 | K40: HENKEL | L40: FMCG | M40: Temizlik Deterjan | N40: Yok | O40: Hayır | P40: İstanbul | Q40: Enroute | R40: Sonlandı
...

Sheet AccountDağılımı-Adet
A3: Count of Şehir | B3: Column Labels
A4: Row Labels | B4: Begüm Hayta | C4: Mülkiye Akdoğaner | D4: Semih Balaban | E4: Melike Akgünlü | F4: Özge Güler | G4: Dilara Bogu | H4: Grand Total
A5: Beyaz Eşya | C5: 2 | H5: 2
A6: Boya | E6: 1 | H6: 1
A7: Cam Sanayi | D7: 2 | H7: 2
A8: Elektrik Elektronik | E8: 2 | H8: 2
A9: Enerji | E9: 2 | H9: 2
A10: FMCG | B10: 24 | C10: 19 | D10: 11 | F10: 17 | H10: 71
A11: Hizmet | F11: 1 | H11: 1
A12: İnşaat | D12: 1 | H12: 1
A13: Madencilik | D13: 1 | H13: 1
A14: Otomotiv | D14: 8 | H14: 8
A15: Petrol | E15: 2 | H15: 2
A16: Sağlık | E16: 1 | H16: 1
A17: Tekstil | D17: 1 | H17: 1
A18: Telekom | F18: 1 | H18: 1
A19: Üretim | F19: 6 | H19: 6
A20: Grup Şirketleri
A21: Grand Total | B21: 24 | C21: 21 | D21: 24 | E21: 8 | F21: 25 | H21: 102
A24: Satış Yöneticisi Sektör | B24: Begüm Hayta | C24: Mülkiye Akdoğaner | D24: Semih Balaban | E24: Melike Akgünlü | F24: Özge Güler | G24: Dilara Bogu | H24: Toplam
A25: Beyaz Eşya | C25: 2 | H25: 2
A26: Boya | E26: 1 | H26: 1
A27: Cam Sanayi | D27: 2 | H27: 2
A28: Elektrik Elektronik | E28: 2 | H28: 2
A29: Enerji | E29: 2 | H29: 2
A30: FMCG | B30: 24 | C30: 19 | D30: 11 | F30: 17 | H30: 71
A31: Hizmet | F31: 1 | H31: 1
A32: İnşaat | D32: 1 | H32: 1
A33: Madencilik | D33: 1 | H33: 1
A34: Otomotiv | D34: 8 | H34: 8
A35: Petrol | E35: 2 | H35: 2
A36: Sağlık | E36: 1 | H36: 1
A37: Tekstil | D37: 1 | H37: 1
A38: Telekom | F38: 1 | H38: 1
A39: Üretim | F39: 6 | H39: 6
A40: Grup Şirketleri | G40: 4 | H40: 6
A41: Toplam | B41: =SUM(B25:B40) -> 24 | C41: =SUM(C25:C40) -> 21 | D41: =SUM(D25:D40) -> 24 | E41: =SUM(E25:E40) -> 8 | F41: =SUM(F25:F40) -> 25 | G41: =SUM(G25:G40) -> 4 | H41: =SUM(H25:H40) -> 108

Sheet 2026 Bütçe - 600 (Yıllık)
I2: Index'e Dön | T2: 2026 Satış Slideları
R3: (07.01.26)
B4: 1 | C4: Ürün Bazında Gelirler (TL) | Q4: Ürün Yön. | R4: Ürün Yön. | T4: Satış Tipi Bazında Gelirler (TL)
C5: Ürünler | D5: 2024 | E5: 2025 Yeni Satış | F5: 2025 Mevcut Müşteri | G5: 2025 (G) | H5: YS Artış% | I5: 2026 Yeni Satış | J5: 2025 Churn | K5: Churn Sonrası MM | L5: MM Artış % | M5: 2026 Mevcut Müşteri | N5: 2026 Bütçe Tahmini 2026 | Q5: 2026 Satış Tahmini | R5: 2026 Satış Tahmini | T5: Satış Tipi | U5: 2025 | V5: 2026 (P) | W5: Büyüme (P)
C6: Enroute | D6: 140500 | E6: 70053.607 | F6: 143242.81 | G6: =SUM(E6:F6) -> 213296.42 | H6: 0.5 | I6: =E6*(1+H6) -> 105080.41 | J6: 9000 | K6: =F6-J6 -> 134242.81 | L6: 0.325 | M6: =K6*(1+L6) -> 177871.73 | N6: =I6+M6 -> 282952.14 | Q6: =N6 -> 282952.14 | R6: 355556878 | T6: Yeni Satış | U6: =E14/1000 -> 152.04434 | V6: =I14/1000 -> 278.85597 | W6: =V6/U6-1 -> 0.83404379
C7: Quest | D7: 16100 | E7: 13752.678 | F7: 13930.924 | G7: =SUM(E7:F7) -> 27683.602 | H7: 2 | I7: =E7*(1+H7) -> 41258.034 | J7: 1515 | K7: =F7-J7 -> 12415.924 | L7: =L6 -> 0.325 | M7: =K7*(1+L7) -> 16451.099 | N7: =I7+M7 -> 57709.133 | Q7: 100000000 | R7: 102262500 | T7: Yenileme | U7: =F14/1000 -> 232.74367 | V7: =M14/1000 -> 321.27624 | W7: =V7/U7-1 -> 0.38038658
C8: Stokbar | D8: 17900 | E8: 25018.01 | F8: 19223.725 | G8: =SUM(E8:F8) -> 44241.735 | H8: 0.5 | I8: =E8*(1+H8) -> 37527.015 | J8: 2310 | K8: =F8-J8 -> 16913.725 | L8: =L7 -> 0.325 | M8: =K8*(1+L8) -> 22410.686 | N8: =I8+M8 -> 59937.701 | Q8: =N8 -> 59937.701 | R8: 95747000 | T8: Toplam | U8: =U6+U7 -> 384.78801 | V8: =V6+V7 -> 600.13221 | W8: =V8/U8-1 -> 0.55964375
C9: ServiceCore | D9: 6000 | E9: 8415.736 | F9: 4773.941 | G9: =SUM(E9:F9) -> 13189.677 | H9: 2 | I9: =E9*(1+H9) -> 25247.208 | J9: 4500 | K9: =F9-J9 -> 273.941 | L9: =L8 -> 0.325 | M9: =K9*(1+L9) -> 362.97182 | N9: =I9+M9 -> 25610.18 | Q9: 43000000 | R9: 34635137
C10: Varuna | D10: 100 | E10: 3806.445 | F10: 2987.175 | G10: =SUM(E10:F10) -> 6793.62 | H10: 0.5 | I10: =E10*(1+H10) -> 5709.6675 | J10: 100 | K10: =F10-J10 -> 2887.175 | L10: =L9 -> 0.325 | M10: =K10*(1+L10) -> 3825.5069 | N10: =I10+M10 -> 9535.1744 | Q10: 16000000 | R10: 16146000
C11: Unidox | D11: 14000 | E11: 25326.464 | F11: 0 | G11: =SUM(E11:F11) -> 25326.464 | H11: 2 | I11: 40000 | K11: =F11-J11 -> 0 | L11: =L10 -> 0.325 | M11: 35979 | N11: =I11+M11 -> 75979 | Q11: =N11 -> 75979 | R11: =N11 -> 75979
C12: Hosting | D12: 35000 | E12: 690.653 | F12: 48585.095 | G12: =SUM(E12:F12) -> 49275.748 | H12: 10 | I12: =E12*(1+H12) -> 7597.183 | K12: =F12-J12 -> 48585.095 | L12: =L11 -> 0.325 | M12: =K12*(1+L12) -> 64375.251 | N12: =I12+M12 -> 71972.434 | Q12: =N12 -> 71972.434 | R12: =N12 -> 71972.434
C13: BFH | D13: 0 | E13: 4980.743 | F13: 0 | G13: =SUM(E13:F13) -> 4980.743 | H13: 2.3 | I13: =E13*(1+H13) -> 16436.452 | K13: =F13-J13 -> 0 | L13: =L12 -> 0.325 | M13: =K13*(1+L13) -> 0 | N13: =I13+M13 -> 16436.452 | Q13: =N13 -> 16436.452 | R13: =N13 -> 16436.452
C14: Toplam | D14: =SUM(D6:D13) -> 229600 | E14: =SUM(E6:E13) -> 152044.34 | F14: =SUM(F6:F13) -> 232743.67 | G14: =SUM(G6:G13) -> 384788.01 | I14: =SUM(I6:I13) -> 278855.97 | J14: =SUM(J6:J13) -> 17425 | K14: =SUM(K6:K13) -> 215318.67 | M14: =SUM(M6:M13) -> 321276.24 | N14: =SUM(N6:N13) -> 600132.21 | Q14: =SUM(Q6:Q13) -> 1.5950728e+08 | R14: =SUM(R6:R13) -> 6.045119e+08
B18: 2 | C18: Ürün Bazında Gelirler (TL) V11 | T18: Ürün Bazında Gelirler (TL)
C19: Ürün Gelirleri | D19: 2025 | G19: 2026 (P) | H19: 2025 Büyüme | I19: 2026 Büyüme (P) | J19: 2026 (P) Büyüme | K19: 2025 Büyüme | L19: 2026 Büyüme (P) | T19: Ürün Gelirleri | U19: 2024 | V19: 2025 | W19: 2026 (P) | X19: 2025 Büyüme | Y19: 2026 Büyüme (P)
D20: Yeni Satış | E20: Yenileme | F20: Toplam | G20: Yeni Satış | H20: Yenileme | I20: Toplam | J20: Yeni Satış | K20: Yenileme | L20: Toplam | T20: Enroute | U20: 140500 | V20: 213296.42 | W20: =N6/1000 -> 282.95214 | X20: =V20/U20-1 -> 0.51812399 | Y20: =W20/V20-1 -> -0.99867343
C21: Enroute | D21: 70053.607 | E21: 143242.81 | F21: =SUM(D21:E21) -> 213296.42 | G21: 105080.41 | H21: 177871.73 | I21: =SUM(G21:H21) -> 282952.14 | J21: =G21/D21-1 -> 0.5 | K21: =H21/E21-1 -> 0.24174975 | L21: =I21/F21-1 -> 0.32656768 | T21: Quest | U21: 16100 | V21: 27683.602 | W21: =N7/1000 -> 57.709133 | X21: =V21/U21-1 -> 0.71947839 | Y21: =W21/V21-1 -> -0.9979154
C22: Quest | D22: 13752.678 | E22: 13930.924 | F22: =SUM(D22:E22) -> 27683.602 | G22: 41258.034 | H22: 16451.099 | I22: =SUM(G22:H22) -> 57709.133 | J22: =G22/D23-1 -> 0.64913332 | K22: =H22/E22-1 -> 0.18090511 | L22: =I22/F22-1 -> 1.0845963 | T22: Stokbar | U22: 17900 | V22: 44241.735 | W22: =N8/1000 -> 59.937701 | X22: =V22/U22-1 -> 1.4716053 | Y22: =W22/V22-1 -> -0.99864522
C23: Stokbar | D23: 25018.01 | E23: 19223.725 | F23: =SUM(D23:E23) -> 44241.735 | G23: 37527.015 | H23: 22410.686 | I23: =SUM(G23:H23) -> 59937.701 | J23: =G23/D24-1 -> 3.4591483 | K23: =H23/E23-1 -> 0.16578268 | L23: =I23/F23-1 -> 0.35477735 | T23: ServiceCore | U23: 6000 | V23: 13189.677 | W23: =N9/1000 -> 25.61018 | X23: =V23/U23-1 -> 1.1982795 | Y23: =W23/V23-1 -> -0.99805832
C24: ServiceCore | D24: 8415.736 | E24: 4773.941 | F24: =SUM(D24:E24) -> 13189.677 | G24: 25247.208 | H24: 362.97182 | I24: =SUM(G24:H24) -> 25610.18 | J24: =G24/D25-1 -> 5.6327526 | K24: =H24/E24-1 -> -0.9239681 | L24: =I24/F24-1 -> 0.94168362 | T24: Varuna | U24: 100 | V24: 6793.62 | W24: =N10/1000 -> 9.5351744 | X24: =V24/U24-1 -> 66.9362 | Y24: =W24/V24-1 -> -0.99859645
C25: Varuna | D25: 3806.445 | E25: 2987.175 | F25: =SUM(D25:E25) -> 6793.62 | G25: 5709.6675 | H25: 3825.5069 | I25: =SUM(G25:H25) -> 9535.1744 | J25: =G25/D25-1 -> 0.5 | K25: =H25/E25-1 -> 0.28064371 | L25: =I25/F25-1 -> 0.40354838 | T25: Unidox | U25: 14000 | V25: 25326.464 | W25: =N11/1000 -> 75.979 | X25: =V25/U25-1 -> 0.80903314 | Y25: =W25/V25-1 -> -0.99700002
C26: Unidox | D26: 25326.464 | E26: 0 | F26: =SUM(D26:E26) -> 25326.464 | G26: 75979.392 | H26: 0 | I26: =SUM(G26:H26) -> 75979.392 | J26: =G26/D26-1 -> 2 | L26: =I26/F26-1 -> 2 | T26: Hosting | U26: 35000 | V26: 49275.748 | W26: =N12/1000 -> 71.972434 | X26: =V26/U26-1 -> 0.40787851 | Y26: =W26/V26-1 -> -0.99853939
C27: Hosting | D27: 690.653 | E27: 48585.095 | F27: =SUM(D27:E27) -> 49275.748 | G27: 7597.183 | H27: 64375.251 | I27: =SUM(G27:H27) -> 71972.434 | J27: =G27/D27-1 -> 10 | K27: =H27/E27-1 -> 0.325 | L27: =I27/F27-1 -> 0.46060561 | T27: BFH | U27: 0 | V27: 4980.743 | W27: =N13/1000 -> 16.436452 | Y27: =W27/V27-1 -> -0.9967
C28: BFH | D28: 4980.743 | E28: 0 | F28: =SUM(D28:E28) -> 4980.743 | G28: 16436.452 | H28: 0 | I28: =SUM(G28:H28) -> 16436.452 | J28: =G28/D28-1 -> 2.3 | L28: =I28/F28-1 -> 2.3 | T28: Toplam | U28: =SUM(U20:U27) -> 229600 | V28: =SUM(V20:V27) -> 384788.01 | W28: =SUM(W20:W27) -> 600.13221 | X28: =V28/U28-1 -> 0.67590596 | Y28: =W28/V28-1 -> -0.99844036
C29: Toplam | D29: =SUM(D21:D28) -> 152044.34 | E29: =SUM(E21:E28) -> 232743.67 | F29: =SUM(F21:F28) -> 384788.01 | G29: =SUM(G21:G28) -> 314835.36 | H29: =SUM(H21:H28) -> 285297.24 | I29: =SUM(I21:I28) -> 600132.6 | J29: =G29/D29-1 -> 1.0706813 | K29: =H29/E29-1 -> 0.2258002 | L29: =I29/F29-1 -> 0.55964476
C31: Hedefler
B32: 1 | C32: Yazılım satışının %20 si kadar ek e-dönüşüm ürünleri satalım | G32: =(F29-F26-F27-F28)*20% -> 61041.011
B33: 2 | C33: Mevcut müşterilerin %75 ne hosting satalım (75-28=47) 350K ortalama | G33: =350*47 -> 16450
B34: 3 | C34: İş ortaklarını sayısını 70 ve üzerine çıkaralım | G34: 70
B35: 4
B36: 5
C38: Yıl | D38: 2025
C40: Sum of Net Satış | D40: Column Labels
C41: Row Labels | D41: Enroute | E41: Stokbar | F41: Quest | G41: Calldesk | H41: Varuna | I41: E-Dönüşüm | J41: Hosting | K41: BFG | L41: Outsource - Hizmet | M41: Grand Total
C42: Begüm Hayta | D42: 68370270 | E42: 16360018 | F42: 6926550.7 | G42: 680114.63 | I42: 872865 | J42: 12610406 | M42: 1.0582022e+08
C43: E-Dönüşüm | I43: 20542744 | M43: 20542744
C44: Eren Oral | D44: 791317.4 | E44: 7802039.5 | F44: 329520.06 | J44: 980595 | L44: 3084150 | M44: 12987622
C45: Grup içi | E45: 543801.2 | M45: 543801.2
C46: Grup İçi | H46: 6336391 | K46: 4646578.3 | M46: 10982969
C47: İş Ortaklıkları | D47: 6736544.7 | E47: 1407664 | F47: 20223 | I47: 4460466 | J47: 549118.22 | M47: 13174016
...

Sheet 2026 Bütçe - 600 (Aylık)
C1: Ürünler | D1: 2026 Tahmin | E1: 1 | F1: 2 | G1: 3 | H1: 4 | I1: 5 | J1: 6 | K1: 7 | L1: 8 | M1: 9 | N1: 10 | O1: 11 | P1: 12 | Q1: Toplam
C2: Enroute | D2: ='2026 Bütçe - 600 (Yıllık)'!N6 -> 282952.14 | E2: =$D2*E$11 -> 19806.65 | F2: =$D2*F$11 -> 19806.65 | G2: =$D2*G$11 -> 28295.214 | H2: =$D2*H$11 -> 19806.65 | I2: =$D2*I$11 -> 19806.65 | J2: =$D2*J$11 -> 31124.735 | K2: =$D2*K$11 -> 16977.128 | L2: =$D2*L$11 -> 16977.128 | ... P2: =$D2*P$11 -> 36783.778 | Q2: =SUM(E2:P2) -> 282952.14
C3: Quest | D3: ='2026 Bütçe - 600 (Yıllık)'!N7 -> 57709.133 | E3: =$D3*E$11 -> 4039.6393 | F3: =$D3*F$11 -> 4039.6393 | G3: =$D3*G$11 -> 5770.9133 | H3: =$D3*H$11 -> 4039.6393 | I3: =$D3*I$11 -> 4039.6393 | J3: =$D3*J$11 -> 6348.0047 | K3: =$D3*K$11 -> 3462.548 | L3: =$D3*L$11 -> 3462.548 | ... P3: =$D3*P$11 -> 7502.1873 | Q3: =SUM(E3:P3) -> 57709.133
C4: Stokbar | D4: ='2026 Bütçe - 600 (Yıllık)'!N8 -> 59937.701 | E4: =$D4*E$11 -> 4195.639 | F4: =$D4*F$11 -> 4195.639 | G4: =$D4*G$11 -> 5993.7701 | H4: =$D4*H$11 -> 4195.639 | I4: =$D4*I$11 -> 4195.639 | J4: =$D4*J$11 -> 6593.1471 | K4: =$D4*K$11 -> 3596.262 | L4: =$D4*L$11 -> 3596.262 | ... P4: =$D4*P$11 -> 7791.9011 | Q4: =SUM(E4:P4) -> 59937.701
C5: CallDesk | D5: ='2026 Bütçe - 600 (Yıllık)'!N9 -> 25610.18 | E5: =$D5*E$11 -> 1792.7126 | F5: =$D5*F$11 -> 1792.7126 | G5: =$D5*G$11 -> 2561.018 | H5: =$D5*H$11 -> 1792.7126 | I5: =$D5*I$11 -> 1792.7126 | J5: =$D5*J$11 -> 2817.1198 | K5: =$D5*K$11 -> 1536.6108 | L5: =$D5*L$11 -> 1536.6108 | ... P5: =$D5*P$11 -> 3329.3234 | Q5: =SUM(E5:P5) -> 25610.18
C6: Varuna | D6: ='2026 Bütçe - 600 (Yıllık)'!N10 -> 9535.1744 | E6: =$D6*E$11 -> 667.46221 | F6: =$D6*F$11 -> 667.46221 | G6: =$D6*G$11 -> 953.51744 | H6: =$D6*H$11 -> 667.46221 | I6: =$D6*I$11 -> 667.46221 | J6: =$D6*J$11 -> 1048.8692 | K6: =$D6*K$11 -> 572.11046 | L6: =$D6*L$11 -> 572.11046 | ... P6: =$D6*P$11 -> 1239.5727 | Q6: =SUM(E6:P6) -> 9535.1744
C7: Unidox | D7: ='2026 Bütçe - 600 (Yıllık)'!N11 -> 75979 | E7: =$D7*E$11 -> 5318.53 | F7: =$D7*F$11 -> 5318.53 | G7: =$D7*G$11 -> 7597.9 | H7: =$D7*H$11 -> 5318.53 | I7: =$D7*I$11 -> 5318.53 | J7: =$D7*J$11 -> 8357.69 | K7: =$D7*K$11 -> 4558.74 | L7: =$D7*L$11 -> 4558.74 | ... P7: =$D7*P$11 -> 9877.27 | Q7: =SUM(E7:P7) -> 75979
C8: Hosting | D8: ='2026 Bütçe - 600 (Yıllık)'!N12 -> 71972.434 | E8: =$D8*E$11 -> 5038.0704 | F8: =$D8*F$11 -> 5038.0704 | G8: =$D8*G$11 -> 7197.2434 | H8: =$D8*H$11 -> 5038.0704 | I8: =$D8*I$11 -> 5038.0704 | J8: =$D8*J$11 -> 7916.9677 | K8: =$D8*K$11 -> 4318.346 | L8: =$D8*L$11 -> 4318.346 | ... P8: =$D8*P$11 -> 9356.4164 | Q8: =SUM(E8:P8) -> 71972.434
C9: BFH | D9: ='2026 Bütçe - 600 (Yıllık)'!N13 -> 16436.452 | E9: =$D9*E$11 -> 1150.5516 | F9: =$D9*F$11 -> 1150.5516 | G9: =$D9*G$11 -> 1643.6452 | H9: =$D9*H$11 -> 1150.5516 | I9: =$D9*I$11 -> 1150.5516 | J9: =$D9*J$11 -> 1808.0097 | K9: =$D9*K$11 -> 986.18711 | L9: =$D9*L$11 -> 986.18711 | ... P9: =$D9*P$11 -> 2136.7387 | Q9: =SUM(E9:P9) -> 16436.452
C10: Toplam | D10: =SUM(D2:D9) -> 600132.21 | E10: =SUM(E2:E9) -> 42009.255 | F10: =SUM(F2:F9) -> 42009.255 | G10: =SUM(G2:G9) -> 60013.221 | H10: =SUM(H2:H9) -> 42009.255 | I10: =SUM(I2:I9) -> 42009.255 | J10: =SUM(J2:J9) -> 66014.543 | K10: =SUM(K2:K9) -> 36007.933 | ... P10: =SUM(P2:P9) -> 78017.188 | Q10: =SUM(E10:P10) -> 600132.21
C11: Genel Toplam | D11: =SUM(D2:D9) -> 600132.21 | E11: 0.07 | F11: 0.07 | G11: 0.1 | H11: 0.07 | I11: 0.07 | J11: 0.11 | K11: 0.06 | L11: 0.06 | M11: 0.1 | N11: 0.08 | O11: 0.08 | P11: 0.13 | Q11: =SUM(E11:P11) -> 1
C15: Ürünler | D15: 2026 Tahmin Düzeltilmiş | E15: 1 | F15: 2 | G15: 3 | H15: 4 | I15: 5 | J15: 6 | K15: 7 | L15: 8 | M15: 9 | N15: 10 | O15: 11 | P15: 12 | Q15: Toplam
C16: Enroute | D16: ='2026 Bütçe - 600 (Yıllık)'!N6 -> 282952.14 | E16: =$D16*E30 -> 19806.65 | F16: =$D16*F30 -> 19806.65 | G16: =$D16*G30 -> 22636.171 | H16: =$D16*H30 -> 21221.41 | I16: =$D16*I30 -> 21221.41 | J16: =$D16*J30 -> 25465.692 | K16: =$D16*K30 -> 21221.41 | L16: =$D16*L30 -> 21221.41 | ... P16: =$D16*P30 -> 31124.735 | Q16: =SUM(E16:P16) -> 282952.14
C17: Quest | D17: ='2026 Bütçe - 600 (Yıllık)'!N7 -> 57709.133 | E17: =$D17*E31 -> 4039.6393 | F17: =$D17*F31 -> 4039.6393 | G17: =$D17*G31 -> 4616.7307 | H17: =$D17*H31 -> 4616.7307 | I17: =$D17*I31 -> 4616.7307 | J17: =$D17*J31 -> 5193.822 | K17: =$D17*K31 -> 4328.185 | L17: =$D17*L31 -> 4328.185 | ... P17: =$D17*P31 -> 6348.0047 | Q17: =SUM(E17:P17) -> 57709.133
C18: Stokbar | D18: ='2026 Bütçe - 600 (Yıllık)'!N8 -> 59937.701 | E18: =$D18*E32 -> 4195.639 | F18: =$D18*F32 -> 4195.639 | G18: =$D18*G32 -> 4795.0161 | H18: =$D18*H32 -> 4795.0161 | I18: =$D18*I32 -> 4795.0161 | J18: =$D18*J32 -> 5394.3931 | K18: =$D18*K32 -> 4495.3275 | L18: =$D18*L32 -> 4495.3275 | ... P18: =$D18*P32 -> 6593.1471 | Q18: =SUM(E18:P18) -> 59937.701
C19: ServiceCore | D19: ='2026 Bütçe - 600 (Yıllık)'!N9 -> 25610.18 | E19: =$D19*E33 -> 1792.7126 | F19: =$D19*F33 -> 1792.7126 | G19: =$D19*G33 -> 2048.8144 | H19: =$D19*H33 -> 2048.8144 | I19: =$D19*I33 -> 2048.8144 | J19: =$D19*J33 -> 2304.9162 | K19: =$D19*K33 -> 1920.7635 | L19: =$D19*L33 -> 1920.7635 | ... P19: =$D19*P33 -> 2817.1198 | Q19: =SUM(E19:P19) -> 25610.18
C20: Varuna | D20: ='2026 Bütçe - 600 (Yıllık)'!N10 -> 9535.1744 | E20: =$D20*E34 -> 667.46221 | F20: =$D20*F34 -> 667.46221 | G20: =$D20*G34 -> 762.81395 | H20: =$D20*H34 -> 762.81395 | I20: =$D20*I34 -> 762.81395 | J20: =$D20*J34 -> 858.16569 | K20: =$D20*K34 -> 715.13808 | L20: =$D20*L34 -> 715.13808 | ... P20: =$D20*P34 -> 1048.8692 | Q20: =SUM(E20:P20) -> 9535.1744
C21: Unidox | D21: ='2026 Bütçe - 600 (Yıllık)'!N11 -> 75979 | E21: =$D21*E35 -> 5318.53 | F21: =$D21*F35 -> 5318.53 | G21: =$D21*G35 -> 6078.32 | H21: =$D21*H35 -> 6078.32 | I21: =$D21*I35 -> 6078.32 | J21: =$D21*J35 -> 6838.11 | K21: =$D21*K35 -> 5698.425 | L21: =$D21*L35 -> 5698.425 | ... P21: =$D21*P35 -> 8357.69 | Q21: =SUM(E21:P21) -> 75979
C22: Hosting | D22: ='2026 Bütçe - 600 (Yıllık)'!N12 -> 71972.434 | E22: =$D22*E36 -> 5038.0704 | F22: =$D22*F36 -> 5038.0704 | G22: =$D22*G36 -> 5757.7947 | H22: =$D22*H36 -> 5757.7947 | I22: =$D22*I36 -> 5757.7947 | J22: =$D22*J36 -> 6477.519 | K22: =$D22*K36 -> 5397.9325 | L22: =$D22*L36 -> 5397.9325 | ... P22: =$D22*P36 -> 7916.9677 | Q22: =SUM(E22:P22) -> 71972.434
C23: BFH | D23: ='2026 Bütçe - 600 (Yıllık)'!N13 -> 16436.452 | E23: =$D23*E37 -> 1314.9162 | F23: =$D23*F37 -> 1314.9162 | G23: =$D23*G37 -> 1479.2807 | H23: =$D23*H37 -> 1314.9162 | I23: =$D23*I37 -> 1314.9162 | J23: =$D23*J37 -> 1479.2807 | K23: =$D23*K37 -> 1232.7339 | L23: =$D23*L37 -> 1314.9162 | ... P23: =$D23*P37 -> 1561.4629 | Q23: =SUM(E23:P23) -> 16436.452
C24: Toplam (TL) | D24: =SUM(D16:D23) -> 600132.21 | E24: =SUM(E16:E23) -> 42173.619 | F24: =SUM(F16:F23) -> 42173.619 | G24: =SUM(G16:G23) -> 48174.941 | H24: =SUM(H16:H23) -> 46595.816 | I24: =SUM(I16:I23) -> 46595.816 | J24: =SUM(J16:J23) -> 54011.899 | K24: =SUM(K16:K23) -> 45009.916 | ... P24: =SUM(P16:P23) -> 65767.997 | Q24: =SUM(E24:P24) -> 600132.21
C25: Toplam (%) | E25: =E39 -> 0.07125 | F25: =F39 -> 0.07125 | G25: =G39 -> 0.08125 | H25: =H39 -> 0.079375 | I25: =I39 -> 0.079375 | J25: =J39 -> 0.09 | K25: =K39 -> 0.075 | L25: =L39 -> 0.075625 | ... P25: =P39 -> 0.108125 | Q25: =SUM(E25:P25) -> 1
C29: Ürünler | D29: 2026 Tahmin Düzeltilmiş | E29: 1 | F29: 2 | G29: 3 | H29: 4 | I29: 5 | J29: 6 | K29: 7 | L29: 8 | M29: 9 | N29: 10 | O29: 11 | P29: 12 | Q29: Toplam
C30: Enroute | D30: =D16 -> 282952.14 | E30: 0.07 | F30: 0.07 | G30: 0.08 | H30: 0.075 | I30: 0.075 | J30: 0.09 | K30: 0.075 | L30: 0.075 | M30: 0.08 | N30: 0.1 | O30: 0.1 | P30: 0.11 | Q30: =SUM(E30:P30) -> 1
C31: Quest | D31: =D17 -> 57709.133 | E31: 0.07 | F31: 0.07 | G31: 0.08 | H31: 0.08 | I31: 0.08 | J31: 0.09 | K31: 0.075 | L31: 0.075 | M31: 0.08 | N31: 0.095 | O31: 0.095 | P31: 0.11 | Q31: =SUM(E31:P31) -> 1
C32: Stokbar | D32: =D18 -> 59937.701 | E32: 0.07 | F32: 0.07 | G32: 0.08 | H32: 0.08 | I32: 0.08 | J32: 0.09 | K32: 0.075 | L32: 0.075 | M32: 0.08 | N32: 0.095 | O32: 0.095 | P32: 0.11 | Q32: =SUM(E32:P32) -> 1
C33: ServiceCore | D33: =D19 -> 25610.18 | E33: 0.07 | F33: 0.07 | G33: 0.08 | H33: 0.08 | I33: 0.08 | J33: 0.09 | K33: 0.075 | L33: 0.075 | M33: 0.08 | N33: 0.095 | O33: 0.095 | P33: 0.11 | Q33: =SUM(E33:P33) -> 1
C34: Varuna | D34: =D20 -> 9535.1744 | E34: 0.07 | F34: 0.07 | G34: 0.08 | H34: 0.08 | I34: 0.08 | J34: 0.09 | K34: 0.075 | L34: 0.075 | M34: 0.08 | N34: 0.095 | O34: 0.095 | P34: 0.11 | Q34: =SUM(E34:P34) -> 1
C35: Unidox | D35: =D21 -> 75979 | E35: 0.07 | F35: 0.07 | G35: 0.08 | H35: 0.08 | I35: 0.08 | J35: 0.09 | K35: 0.075 | L35: 0.075 | M35: 0.08 | N35: 0.095 | O35: 0.095 | P35: 0.11 | Q35: =SUM(E35:P35) -> 1
C36: Hosting | D36: =D22 -> 71972.434 | E36: 0.07 | F36: 0.07 | G36: 0.08 | H36: 0.08 | I36: 0.08 | J36: 0.09 | K36: 0.075 | L36: 0.075 | M36: 0.08 | N36: 0.095 | O36: 0.095 | P36: 0.11 | Q36: =SUM(E36:P36) -> 1
C37: BFH | D37: =D23 -> 16436.452 | E37: 0.08 | F37: 0.08 | G37: 0.09 | H37: 0.08 | I37: 0.08 | J37: 0.09 | K37: 0.075 | L37: 0.08 | M37: 0.08 | N37: 0.08 | O37: 0.09 | P37: 0.095 | Q37: =SUM(E37:P37) -> 1
C38: Toplam (TL) | D38: =SUM(D30:D37) -> 600132.21
C39: Aylık Ciro Payı (%) | E39: =AVERAGE(E30:E37) -> 0.07125 | F39: =AVERAGE(F30:F37) -> 0.07125 | G39: =AVERAGE(G30:G37) -> 0.08125 | H39: =AVERAGE(H30:H37) -> 0.079375 | I39: =AVERAGE(I30:I37) -> 0.079375 | J39: =AVERAGE(J30:J37) -> 0.09 | K39: =AVERAGE(K30:K37) -> 0.075 | L39: =AVERAGE(L30:L37) -> 0.075625 | ... P39: =AVERAGE(P30:P37) -> 0.108125 | Q39: =SUM(E39:P39) -> 1

Sheet Ürün YS-YenilemeHedefleri - 600
A1: Satış Hedef Bütçe - Ürün-Gelir Tipi Bazında (2026)
A2: Net Satış M TL | B2: Enroute | C2: Quest | D2: Stokbar | E2: ServiceCore | F2: Varuna | G2: E-Dönüşüm | H2: Hosting | I2: BFG | J2: Grand Total
A3: Direk+Endirek Satış Toplam | B3: ='2026 Bütçe - 600 (Aylık)'!D16 -> 282952.14 | C3: ='2026 Bütçe - 600 (Aylık)'!D17 -> 57709.133 | D3: ='2026 Bütçe - 600 (Aylık)'!D18 -> 59937.701 | E3: ='2026 Bütçe - 600 (Aylık)'!D19 -> 25610.18 | F3: ='2026 Bütçe - 600 (Aylık)'!D20 -> 9535.1744 | G3: ='2026 Bütçe - 600 (Aylık)'!D21 -> 75979 | H3: ='2026 Bütçe - 600 (Aylık)'!D22 -> 71972.434 | I3: ='2026 Bütçe - 600 (Aylık)'!D23 -> 16436.452 | J3: =SUM(B3:I3) -> 600132.21
A4: Yeni Satış | B4: ='2026 Bütçe - 600 (Yıllık)'!I6 -> 105080.41 | C4: ='2026 Bütçe - 600 (Yıllık)'!I7 -> 41258.034 | D4: ='2026 Bütçe - 600 (Yıllık)'!I8 -> 37527.015 | E4: ='2026 Bütçe - 600 (Yıllık)'!I9 -> 25247.208 | F4: ='2026 Bütçe - 600 (Yıllık)'!I10 -> 5709.6675 | G4: ='2026 Bütçe - 600 (Yıllık)'!I11 -> 40000 | H4: ='2026 Bütçe - 600 (Yıllık)'!I12 -> 7597.183 | I4: ='2026 Bütçe - 600 (Yıllık)'!I13 -> 16436.452 | J4: =SUM(B4:I4) -> 278855.97
A5: Yenileme | B5: ='2026 Bütçe - 600 (Yıllık)'!M6 -> 177871.73 | C5: ='2026 Bütçe - 600 (Yıllık)'!M7 -> 16451.099 | D5: ='2026 Bütçe - 600 (Yıllık)'!M8 -> 22410.686 | E5: ='2026 Bütçe - 600 (Yıllık)'!M9 -> 362.97182 | F5: ='2026 Bütçe - 600 (Yıllık)'!M10 -> 3825.5069 | G5: ='2026 Bütçe - 600 (Yıllık)'!M11 -> 35979 | H5: ='2026 Bütçe - 600 (Yıllık)'!M12 -> 64375.251 | I5: ='2026 Bütçe - 600 (Yıllık)'!M13 -> 0 | J5: =SUM(B5:I5) -> 321276.24
A7: Yeni Satış | B7: =B4/B$3 -> 0.37137168 | C7: =C4/C$3 -> 0.71493075 | D7: =D4/D$3 -> 0.62610034 | E7: =E4/E$3 -> 0.98582705 | F7: =F4/F$3 -> 0.59880053 | G7: =G4/G$3 -> 0.52646126 | H7: =H4/H$3 -> 0.10555684 | I7: =I4/I$3 -> 1 | J7: =J4/J$3 -> 0.46465756
A8: Yenileme | B8: =B5/B$3 -> 0.62862832 | C8: =C5/C$3 -> 0.28506925 | D8: =D5/D$3 -> 0.37389966 | E8: =E5/E$3 -> 0.014172951 | F8: =F5/F$3 -> 0.40119947 | G8: =G5/G$3 -> 0.47353874 | H8: =H5/H$3 -> 0.89444316 | I8: =I5/I$3 -> 0 | J8: =J5/J$3 -> 0.53534244
A11: 2026 Yılı Ürünbazında Yeni Satış ve Yenileme Aylık Hedefleri Tablosu | P11: 2026 Yılı Çeyrekler Bazında Ciro
A12: Ürünler | B12: 1 | C12: 2 | D12: 3 | E12: 4 | F12: 5 | G12: 6 | H12: 7 | I12: 8 | J12: 9 | K12: 10 | L12: 11 | M12: 12 | N12: Toplam | P12: Ürünler | Q12: 1 | R12: 2 | S12: 3 | T12: 4 | U12: Toplam
A13: Enroute | B13: ='2026 Bütçe - 600 (Aylık)'!E16 -> 19806.65 | C13: ='2026 Bütçe - 600 (Aylık)'!F16 -> 19806.65 | D13: ='2026 Bütçe - 600 (Aylık)'!G16 -> 22636.171 | E13: ='2026 Bütçe - 600 (Aylık)'!H16 -> 21221.41 | F13: ='2026 Bütçe - 600 (Aylık)'!I16 -> 21221.41 | G13: ='2026 Bütçe - 600 (Aylık)'!J16 -> 25465.692 | H13: ='2026 Bütçe - 600 (Aylık)'!K16 -> 21221.41 | I13: ='2026 Bütçe - 600 (Aylık)'!L16 -> 21221.41 | ... M13: ='2026 Bütçe - 600 (Aylık)'!P16 -> 31124.735 | N13: =SUM(B13:M13) -> 282952.14 | P13: Enroute | Q13: =SUM(B13:D13) -> 62249.47 | R13: =SUM(E13:G13) -> 67908.513 | S13: =SUM(H13:J13) -> 65078.992 | T13: =SUM(K13:M13) -> 87715.163 | U13: =SUM(Q13:T13) -> 282952.14
A14: Yeni Satış | B14: =$B$7*B13 -> 7355.6287 | C14: =$B$7*C13 -> 7355.6287 | D14: =$B$7*D13 -> 8406.4328 | E14: =$B$7*E13 -> 7881.0308 | F14: =$B$7*F13 -> 7881.0308 | G14: =$B$7*G13 -> 9457.2369 | H14: =$B$7*H13 -> 7881.0308 | I14: =$B$7*I13 -> 7881.0308 | ... M14: =$B$7*M13 -> 11558.845 | N14: =SUM(B14:M14) -> 105080.41 | P14: Yeni Satış | Q14: =SUM(B14:D14) -> 23117.69 | R14: =SUM(E14:G14) -> 25219.299 | S14: =SUM(H14:J14) -> 24168.494 | T14: =SUM(K14:M14) -> 32574.927 | U14: =SUM(Q14:T14) -> 105080.41
A15: Yenileme | B15: =$B$8*B13 -> 12451.021 | C15: =$B$8*C13 -> 12451.021 | D15: =$B$8*D13 -> 14229.738 | E15: =$B$8*E13 -> 13340.38 | F15: =$B$8*F13 -> 13340.38 | G15: =$B$8*G13 -> 16008.455 | H15: =$B$8*H13 -> 13340.38 | I15: =$B$8*I13 -> 13340.38 | ... M15: =$B$8*M13 -> 19565.89 | N15: =SUM(B15:M15) -> 177871.73 | P15: Yenileme | Q15: =SUM(B15:D15) -> 39131.78 | R15: =SUM(E15:G15) -> 42689.215 | S15: =SUM(H15:J15) -> 40910.497 | T15: =SUM(K15:M15) -> 55140.235 | U15: =SUM(Q15:T15) -> 177871.73
A16: Quest | B16: ='2026 Bütçe - 600 (Aylık)'!E17 -> 4039.6393 | C16: ='2026 Bütçe - 600 (Aylık)'!F17 -> 4039.6393 | D16: ='2026 Bütçe - 600 (Aylık)'!G17 -> 4616.7307 | E16: ='2026 Bütçe - 600 (Aylık)'!H17 -> 4616.7307 | F16: ='2026 Bütçe - 600 (Aylık)'!I17 -> 4616.7307 | G16: ='2026 Bütçe - 600 (Aylık)'!J17 -> 5193.822 | H16: ='2026 Bütçe - 600 (Aylık)'!K17 -> 4328.185 | I16: ='2026 Bütçe - 600 (Aylık)'!L17 -> 4328.185 | ... M16: ='2026 Bütçe - 600 (Aylık)'!P17 -> 6348.0047 | N16: =SUM(B16:M16) -> 57709.133 | P16: Quest | Q16: =SUM(B16:D16) -> 12696.009 | R16: =SUM(E16:G16) -> 14427.283 | S16: =SUM(H16:J16) -> 13273.101 | T16: =SUM(K16:M16) -> 17312.74 | U16: =SUM(Q16:T16) -> 57709.133 | Y16: Yeni Müşteri | Z16: Mevcut Müşteri
A17: Yeni Satış | B17: =B16*$C$7 -> 2888.0624 | C17: =C16*$C$7 -> 2888.0624 | D17: =D16*$C$7 -> 3300.6427 | E17: =E16*$C$7 -> 3300.6427 | F17: =F16*$C$7 -> 3300.6427 | G17: =G16*$C$7 -> 3713.2231 | H17: =H16*$C$7 -> 3094.3525 | I17: =I16*$C$7 -> 3094.3525 | ... M17: =M16*$C$7 -> 4538.3837 | N17: =SUM(B17:M17) -> 41258.034 | P17: Yeni Satış | Q17: =SUM(B17:D17) -> 9076.7675 | R17: =SUM(E17:G17) -> 10314.509 | S17: =SUM(H17:J17) -> 9489.3478 | T17: =SUM(K17:M17) -> 12377.41 | U17: =SUM(Q17:T17) -> 41258.034 | X17: Yeni Ürün | Y17: Yeni Satış | Z17: Yeni Satış
A18: Yenileme | B18: =B16*$C$8 -> 1151.577 | C18: =C16*$C$8 -> 1151.577 | D18: =D16*$C$8 -> 1316.0879 | E18: =E16*$C$8 -> 1316.0879 | F18: =F16*$C$8 -> 1316.0879 | G18: =G16*$C$8 -> 1480.5989 | H18: =H16*$C$8 -> 1233.8324 | I18: =I16*$C$8 -> 1233.8324 | ... M18: =M16*$C$8 -> 1809.6209 | N18: =SUM(B18:M18) -> 16451.099 | P18: Yenileme | Q18: =SUM(B18:D18) -> 3619.2418 | R18: =SUM(E18:G18) -> 4112.7748 | S18: =SUM(H18:J18) -> 3783.7528 | T18: =SUM(K18:M18) -> 4935.3298 | U18: =SUM(Q18:T18) -> 16451.099 | X18: Mevcut Ürün | Y18: Yeni Satış | Z18: Yenileme
A19: Stokbar | B19: ='2026 Bütçe - 600 (Aylık)'!E18 -> 4195.639 | C19: ='2026 Bütçe - 600 (Aylık)'!F18 -> 4195.639 | D19: ='2026 Bütçe - 600 (Aylık)'!G18 -> 4795.0161 | E19: ='2026 Bütçe - 600 (Aylık)'!H18 -> 4795.0161 | F19: ='2026 Bütçe - 600 (Aylık)'!I18 -> 4795.0161 | G19: ='2026 Bütçe - 600 (Aylık)'!J18 -> 5394.3931 | H19: ='2026 Bütçe - 600 (Aylık)'!K18 -> 4495.3275 | I19: ='2026 Bütçe - 600 (Aylık)'!L18 -> 4495.3275 | ... M19: ='2026 Bütçe - 600 (Aylık)'!P18 -> 6593.1471 | N19: =SUM(B19:M19) -> 59937.701 | P19: Stokbar | Q19: =SUM(B19:D19) -> 13186.294 | R19: =SUM(E19:G19) -> 14984.425 | S19: =SUM(H19:J19) -> 13785.671 | T19: =SUM(K19:M19) -> 17981.31 | U19: =SUM(Q19:T19) -> 59937.701
A20: Yeni Satış | B20: =B19*$D$7 -> 2626.8911 | C20: =C19*$D$7 -> 2626.8911 | D20: =D19*$D$7 -> 3002.1612 | E20: =E19*$D$7 -> 3002.1612 | F20: =F19*$D$7 -> 3002.1612 | G20: =G19*$D$7 -> 3377.4314 | H20: =H19*$D$7 -> 2814.5261 | I20: =I19*$D$7 -> 2814.5261 | ... M20: =M19*$D$7 -> 4127.9717 | N20: =SUM(B20:M20) -> 37527.015 | P20: Yeni Satış | Q20: =SUM(B20:D20) -> 8255.9433 | R20: =SUM(E20:G20) -> 9381.7538 | S20: =SUM(H20:J20) -> 8631.2134 | T20: =SUM(K20:M20) -> 11258.105 | U20: =SUM(Q20:T20) -> 37527.015
A21: Yenileme | B21: =B19*$D$8 -> 1568.748 | C21: =C19*$D$8 -> 1568.748 | D21: =D19*$D$8 -> 1792.8548 | E21: =E19*$D$8 -> 1792.8548 | F21: =F19*$D$8 -> 1792.8548 | G21: =G19*$D$8 -> 2016.9617 | H21: =H19*$D$8 -> 1680.8014 | I21: =I19*$D$8 -> 1680.8014 | ... M21: =M19*$D$8 -> 2465.1754 | N21: =SUM(B21:M21) -> 22410.686 | P21: Yenileme | Q21: =SUM(B21:D21) -> 4930.3508 | R21: =SUM(E21:G21) -> 5602.6714 | S21: =SUM(H21:J21) -> 5154.4577 | T21: =SUM(K21:M21) -> 6723.2057 | U21: =SUM(Q21:T21) -> 22410.686
A22: ServiceCore | B22: ='2026 Bütçe - 600 (Aylık)'!E19 -> 1792.7126 | C22: ='2026 Bütçe - 600 (Aylık)'!F19 -> 1792.7126 | D22: ='2026 Bütçe - 600 (Aylık)'!G19 -> 2048.8144 | E22: ='2026 Bütçe - 600 (Aylık)'!H19 -> 2048.8144 | F22: ='2026 Bütçe - 600 (Aylık)'!I19 -> 2048.8144 | G22: ='2026 Bütçe - 600 (Aylık)'!J19 -> 2304.9162 | H22: ='2026 Bütçe - 600 (Aylık)'!K19 -> 1920.7635 | I22: ='2026 Bütçe - 600 (Aylık)'!L19 -> 1920.7635 | ... M22: ='2026 Bütçe - 600 (Aylık)'!P19 -> 2817.1198 | N22: =SUM(B22:M22) -> 25610.18 | P22: ServiceCore | Q22: =SUM(B22:D22) -> 5634.2396 | R22: =SUM(E22:G22) -> 6402.545 | S22: =SUM(H22:J22) -> 5890.3414 | T22: =SUM(K22:M22) -> 7683.0539 | U22: =SUM(Q22:T22) -> 25610.18
A23: Yeni Satış | B23: =B22*$E$7 -> 1767.3046 | C23: =C22*$E$7 -> 1767.3046 | D23: =D22*$E$7 -> 2019.7766 | E23: =E22*$E$7 -> 2019.7766 | F23: =F22*$E$7 -> 2019.7766 | G23: =G22*$E$7 -> 2272.2487 | H23: =H22*$E$7 -> 1893.5406 | I23: =I22*$E$7 -> 1893.5406 | ... M23: =M22*$E$7 -> 2777.1929 | N23: =SUM(B23:M23) -> 25247.208 | P23: Yeni Satış | Q23: =SUM(B23:D23) -> 5554.3858 | R23: =SUM(E23:G23) -> 6311.802 | S23: =SUM(H23:J23) -> 5806.8578 | T23: =SUM(K23:M23) -> 7574.1624 | U23: =SUM(Q23:T23) -> 25247.208
A24: Yenileme | B24: =B22*$E$8 -> 25.408028 | C24: =C22*$E$8 -> 25.408028 | D24: =D22*$E$8 -> 29.037746 | E24: =E22*$E$8 -> 29.037746 | F24: =F22*$E$8 -> 29.037746 | G24: =G22*$E$8 -> 32.667464 | H24: =H22*$E$8 -> 27.222887 | I24: =I22*$E$8 -> 27.222887 | ... M24: =M22*$E$8 -> 39.926901 | N24: =SUM(B24:M24) -> 362.97182 | P24: Yenileme | Q24: =SUM(B24:D24) -> 79.853801 | R24: =SUM(E24:G24) -> 90.742956 | S24: =SUM(H24:J24) -> 83.48352 | T24: =SUM(K24:M24) -> 108.89155 | U24: =SUM(Q24:T24) -> 362.97182
A25: Varuna | B25: ='2026 Bütçe - 600 (Aylık)'!E20 -> 667.46221 | C25: ='2026 Bütçe - 600 (Aylık)'!F20 -> 667.46221 | D25: ='2026 Bütçe - 600 (Aylık)'!G20 -> 762.81395 | E25: ='2026 Bütçe - 600 (Aylık)'!H20 -> 762.81395 | F25: ='2026 Bütçe - 600 (Aylık)'!I20 -> 762.81395 | G25: ='2026 Bütçe - 600 (Aylık)'!J20 -> 858.16569 | H25: ='2026 Bütçe - 600 (Aylık)'!K20 -> 715.13808 | I25: ='2026 Bütçe - 600 (Aylık)'!L20 -> 715.13808 | ... M25: ='2026 Bütçe - 600 (Aylık)'!P20 -> 1048.8692 | N25: =SUM(B25:M25) -> 9535.1744 | P25: Varuna | Q25: =SUM(B25:D25) -> 2097.7384 | R25: =SUM(E25:G25) -> 2383.7936 | S25: =SUM(H25:J25) -> 2193.0901 | T25: =SUM(K25:M25) -> 2860.5523 | U25: =SUM(Q25:T25) -> 9535.1744
A26: Yeni Satış | B26: =B25*$F$7 -> 399.67673 | C26: =C25*$F$7 -> 399.67673 | D26: =D25*$F$7 -> 456.7734 | E26: =E25*$F$7 -> 456.7734 | F26: =F25*$F$7 -> 456.7734 | G26: =G25*$F$7 -> 513.87008 | H26: =H25*$F$7 -> 428.22506 | I26: =I25*$F$7 -> 428.22506 | ... M26: =M25*$F$7 -> 628.06343 | N26: =SUM(B26:M26) -> 5709.6675 | P26: Yeni Satış | Q26: =SUM(B26:D26) -> 1256.1269 | R26: =SUM(E26:G26) -> 1427.4169 | S26: =SUM(H26:J26) -> 1313.2235 | T26: =SUM(K26:M26) -> 1712.9003 | U26: =SUM(Q26:T26) -> 5709.6675
A27: Yenileme | B27: =B25*$F$8 -> 267.78548 | C27: =C25*$F$8 -> 267.78548 | D27: =D25*$F$8 -> 306.04055 | E27: =E25*$F$8 -> 306.04055 | F27: =F25*$F$8 -> 306.04055 | G27: =G25*$F$8 -> 344.29562 | H27: =H25*$F$8 -> 286.91302 | I27: =I25*$F$8 -> 286.91302 | ... M27: =M25*$F$8 -> 420.80576 | N27: =SUM(B27:M27) -> 3825.5069 | P27: Yenileme | Q27: =SUM(B27:D27) -> 841.61151 | R27: =SUM(E27:G27) -> 956.37672 | S27: =SUM(H27:J27) -> 879.86658 | T27: =SUM(K27:M27) -> 1147.6521 | U27: =SUM(Q27:T27) -> 3825.5069
A28: Unidox | B28: ='2026 Bütçe - 600 (Aylık)'!E21 -> 5318.53 | C28: ='2026 Bütçe - 600 (Aylık)'!F21 -> 5318.53 | D28: ='2026 Bütçe - 600 (Aylık)'!G21 -> 6078.32 | E28: ='2026 Bütçe - 600 (Aylık)'!H21 -> 6078.32 | F28: ='2026 Bütçe - 600 (Aylık)'!I21 -> 6078.32 | G28: ='2026 Bütçe - 600 (Aylık)'!J21 -> 6838.11 | H28: ='2026 Bütçe - 600 (Aylık)'!K21 -> 5698.425 | I28: ='2026 Bütçe - 600 (Aylık)'!L21 -> 5698.425 | ... M28: ='2026 Bütçe - 600 (Aylık)'!P21 -> 8357.69 | N28: =SUM(B28:M28) -> 75979 | P28: Unidox | Q28: =SUM(B28:D28) -> 16715.38 | R28: =SUM(E28:G28) -> 18994.75 | S28: =SUM(H28:J28) -> 17475.17 | T28: =SUM(K28:M28) -> 22793.7 | U28: =SUM(Q28:T28) -> 75979
A29: Yeni Satış | B29: =B28*$G$7 -> 2800 | C29: =C28*$G$7 -> 2800 | D29: =D28*$G$7 -> 3200 | E29: =E28*$G$7 -> 3200 | F29: =F28*$G$7 -> 3200 | G29: =G28*$G$7 -> 3600 | H29: =H28*$G$7 -> 3000 | I29: =I28*$G$7 -> 3000 | ... M29: =M28*$G$7 -> 4400 | N29: =SUM(B29:M29) -> 40000 | P29: Yeni Satış | Q29: =SUM(B29:D29) -> 8800 | R29: =SUM(E29:G29) -> 10000 | S29: =SUM(H29:J29) -> 9200 | T29: =SUM(K29:M29) -> 12000 | U29: =SUM(Q29:T29) -> 40000
A30: Yenileme | B30: =B28*$G$8 -> 2518.53 | C30: =C28*$G$8 -> 2518.53 | D30: =D28*$G$8 -> 2878.32 | E30: =E28*$G$8 -> 2878.32 | F30: =F28*$G$8 -> 2878.32 | G30: =G28*$G$8 -> 3238.11 | H30: =H28*$G$8 -> 2698.425 | I30: =I28*$G$8 -> 2698.425 | ... M30: =M28*$G$8 -> 3957.69 | N30: =SUM(B30:M30) -> 35979 | P30: Yenileme | Q30: =SUM(B30:D30) -> 7915.38 | R30: =SUM(E30:G30) -> 8994.75 | S30: =SUM(H30:J30) -> 8275.17 | T30: =SUM(K30:M30) -> 10793.7 | U30: =SUM(Q30:T30) -> 35979
A31: Hosting | B31: ='2026 Bütçe - 600 (Aylık)'!E22 -> 5038.0704 | C31: ='2026 Bütçe - 600 (Aylık)'!F22 -> 5038.0704 | D31: ='2026 Bütçe - 600 (Aylık)'!G22 -> 5757.7947 | E31: ='2026 Bütçe - 600 (Aylık)'!H22 -> 5757.7947 | F31: ='2026 Bütçe - 600 (Aylık)'!I22 -> 5757.7947 | G31: ='2026 Bütçe - 600 (Aylık)'!J22 -> 6477.519 | H31: ='2026 Bütçe - 600 (Aylık)'!K22 -> 5397.9325 | I31: ='2026 Bütçe - 600 (Aylık)'!L22 -> 5397.9325 | ... M31: ='2026 Bütçe - 600 (Aylık)'!P22 -> 7916.9677 | N31: =SUM(B31:M31) -> 71972.434 | P31: Hosting | Q31: =SUM(B31:D31) -> 15833.935 | R31: =SUM(E31:G31) -> 17993.108 | S31: =SUM(H31:J31) -> 16553.66 | T31: =SUM(K31:M31) -> 21591.73 | U31: =SUM(Q31:T31) -> 71972.434
A32: Yeni Satış | B32: =B31*$H$7 -> 531.80281 | C32: =C31*$H$7 -> 531.80281 | D32: =D31*$H$7 -> 607.77464 | E32: =E31*$H$7 -> 607.77464 | F32: =F31*$H$7 -> 607.77464 | G32: =G31*$H$7 -> 683.74647 | H32: =H31*$H$7 -> 569.78872 | I32: =I31*$H$7 -> 569.78872 | ... M32: =M31*$H$7 -> 835.69013 | N32: =SUM(B32:M32) -> 7597.183 | P32: Yeni Satış | Q32: =SUM(B32:D32) -> 1671.3803 | R32: =SUM(E32:G32) -> 1899.2957 | S32: =SUM(H32:J32) -> 1747.3521 | T32: =SUM(K32:M32) -> 2279.1549 | U32: =SUM(Q32:T32) -> 7597.183
A33: Yenileme | B33: =B31*$H$8 -> 4506.2676 | C33: =C31*$H$8 -> 4506.2676 | D33: =D31*$H$8 -> 5150.0201 | E33: =E31*$H$8 -> 5150.0201 | F33: =F31*$H$8 -> 5150.0201 | G33: =G31*$H$8 -> 5793.7726 | H33: =H31*$H$8 -> 4828.1438 | I33: =I31*$H$8 -> 4828.1438 | ... M33: =M31*$H$8 -> 7081.2776 | N33: =SUM(B33:M33) -> 64375.251 | P33: Yenileme | Q33: =SUM(B33:D33) -> 14162.555 | R33: =SUM(E33:G33) -> 16093.813 | S33: =SUM(H33:J33) -> 14806.308 | T33: =SUM(K33:M33) -> 19312.575 | U33: =SUM(Q33:T33) -> 64375.251
A34: BFH | B34: ='2026 Bütçe - 600 (Aylık)'!E23 -> 1314.9162 | C34: ='2026 Bütçe - 600 (Aylık)'!F23 -> 1314.9162 | D34: ='2026 Bütçe - 600 (Aylık)'!G23 -> 1479.2807 | E34: ='2026 Bütçe - 600 (Aylık)'!H23 -> 1314.9162 | F34: ='2026 Bütçe - 600 (Aylık)'!I23 -> 1314.9162 | G34: ='2026 Bütçe - 600 (Aylık)'!J23 -> 1479.2807 | H34: ='2026 Bütçe - 600 (Aylık)'!K23 -> 1232.7339 | I34: ='2026 Bütçe - 600 (Aylık)'!L23 -> 1314.9162 | ... M34: ='2026 Bütçe - 600 (Aylık)'!P23 -> 1561.4629 | N34: =SUM(B34:M34) -> 16436.452 | P34: BFH | Q34: =SUM(B34:D34) -> 4109.113 | R34: =SUM(E34:G34) -> 4109.113 | S34: =SUM(H34:J34) -> 3862.5662 | T34: =SUM(K34:M34) -> 4355.6598 | U34: =SUM(Q34:T34) -> 16436.452
A35: Yeni Satış | B35: =B34*$I$7 -> 1314.9162 | C35: =C34*$I$7 -> 1314.9162 | D35: =D34*$I$7 -> 1479.2807 | E35: =E34*$I$7 -> 1314.9162 | F35: =F34*$I$7 -> 1314.9162 | G35: =G34*$I$7 -> 1479.2807 | H35: =H34*$I$7 -> 1232.7339 | I35: =I34*$I$7 -> 1314.9162 | ... M35: =M34*$I$7 -> 1561.4629 | N35: =SUM(B35:M35) -> 16436.452 | P35: Yeni Satış | Q35: =SUM(B35:D35) -> 4109.113 | R35: =SUM(E35:G35) -> 4109.113 | S35: =SUM(H35:J35) -> 3862.5662 | T35: =SUM(K35:M35) -> 4355.6598 | U35: =SUM(Q35:T35) -> 16436.452
A36: Yenileme | B36: =B34*$I$8 -> 0 | C36: =C34*$I$8 -> 0 | D36: =D34*$I$8 -> 0 | E36: =E34*$I$8 -> 0 | F36: =F34*$I$8 -> 0 | G36: =G34*$I$8 -> 0 | H36: =H34*$I$8 -> 0 | I36: =I34*$I$8 -> 0 | ... M36: =M34*$I$8 -> 0 | N36: =SUM(B36:M36) -> 0 | P36: Yenileme | Q36: =SUM(B36:D36) -> 0 | R36: =SUM(E36:G36) -> 0 | S36: =SUM(H36:J36) -> 0 | T36: =SUM(K36:M36) -> 0 | U36: =SUM(Q36:T36) -> 0
A37: Toplam Yeni Satış | B37: =SUMIF($A$13:$A$36,"Yeni Satış",B13:B36) -> 19684.282 | C37: =SUMIF($A$13:$A$36,"Yeni Satış",C13:C36) -> 19684.282 | D37: =SUMIF($A$13:$A$36,"Yeni Satış",D13:D36) -> 22472.842 | E37: =SUMIF($A$13:$A$36,"Yeni Satış",E13:E36) -> 21783.076 | F37: =SUMIF($A$13:$A$36,"Yeni Satış",F13:F36) -> 21783.076 | G37: =SUMIF($A$13:$A$36,"Yeni Satış",G13:G36) -> 25097.037 | H37: =SUMIF($A$13:$A$36,"Yeni Satış",H13:H36) -> 20914.198 | I37: =SUMIF($A$13:$A$36,"Yeni Satış",I13:I36) -> 20996.38 | ... N37: =SUMIF($A$13:$A$36,"Yeni Satış",N13:N36) -> 278855.97 | P37: Toplam Yeni Satış | Q37: =SUMIF($A$13:$A$36,"Yeni Satış",Q13:Q36) -> 61841.407 | R37: =SUMIF($A$13:$A$36,"Yeni Satış",R13:R36) -> 68663.188 | S37: =SUMIF($A$13:$A$36,"Yeni Satış",S13:S36) -> 64219.055 | T37: =SUMIF($A$13:$A$36,"Yeni Satış",T13:T36) -> 84132.319 | U37: =SUMIF($A$13:$A$36,"Yeni Satış",U13:U36) -> 278855.97
A38: Toplam Yenileme | B38: =SUMIF($A$13:$A$36,"Yeni Satış",B14:B37) -> 22489.337 | C38: =SUMIF($A$13:$A$36,"Yeni Satış",C14:C37) -> 22489.337 | D38: =SUMIF($A$13:$A$36,"Yeni Satış",D14:D37) -> 25702.099 | E38: =SUMIF($A$13:$A$36,"Yeni Satış",E14:E37) -> 24812.741 | F38: =SUMIF($A$13:$A$36,"Yeni Satış",F14:F37) -> 24812.741 | G38: =SUMIF($A$13:$A$36,"Yeni Satış",G14:G37) -> 28914.862 | H38: =SUMIF($A$13:$A$36,"Yeni Satış",H14:H37) -> 24095.718 | I38: =SUMIF($A$13:$A$36,"Yeni Satış",I14:I37) -> 24095.718 | ... N38: =SUMIF($A$13:$A$36,"Yeni Satış",N14:N37) -> 321276.24 | P38: Toplam Yenileme | Q38: =SUMIF($A$13:$A$36,"Yeni Satış",Q14:Q37) -> 70680.773 | R38: =SUMIF($A$13:$A$36,"Yeni Satış",R14:R37) -> 78540.343 | S38: =SUMIF($A$13:$A$36,"Yeni Satış",S14:S37) -> 73893.536 | T38: =SUMIF($A$13:$A$36,"Yeni Satış",T14:T37) -> 98161.59 | U38: =SUMIF($A$13:$A$36,"Yeni Satış",U14:U37) -> 321276.24
A39: Toplam (TL) | B39: =SUM(B37:B38) -> 42173.619 | C39: =SUM(C37:C38) -> 42173.619 | D39: =SUM(D37:D38) -> 48174.941 | E39: =SUM(E37:E38) -> 46595.816 | F39: =SUM(F37:F38) -> 46595.816 | G39: =SUM(G37:G38) -> 54011.899 | H39: =SUM(H37:H38) -> 45009.916 | I39: =SUM(I37:I38) -> 45092.098 | ... N39: =SUM(N37:N38) -> 600132.21 | P39: Toplam | Q39: =SUM(Q37:Q38) -> 132522.18 | R39: =SUM(R37:R38) -> 147203.53 | S39: =SUM(S37:S38) -> 138112.59 | T39: =SUM(T37:T38) -> 182293.91 | U39: =SUM(U37:U38) -> 600132.21
A40: Toplam (%) | B40: 0.071 | C40: 0.071 | D40: 0.081 | E40: 0.079 | F40: 0.079 | G40: 0.09 | H40: 0.075 | I40: 0.076 | J40: 0.08 | K40: 0.094 | L40: 0.095 | M40: 0.108 | N40: 1 | P40: Toplam (%) | Q40: =Q39/N39 -> 0.22082164 | R40: =R39/N39 -> 0.24528517 | S40: =S39/N39 -> 0.23013694 | T40: =T39/N39 -> 0.30375625 | U40: =U39/N39 -> 1
E42: 132522
A43: 2026 Yılı Aylık Ciro Dağılım Tablosu | P43: 2026 Yılı Çeyrekler Bazında Ciro Dağılım Tablosu
A44: Ürünler | B44: 1 | C44: 2 | D44: 3 | E44: 4 | F44: 5 | G44: 6 | H44: 7 | I44: 8 | J44: 9 | K44: 10 | L44: 11 | M44: 12 | N44: Toplam | P44: Ürünler | Q44: 1 | R44: 2 | S44: 3 | T44: 4 | U44: Toplam
...

Sheet SatışEkibi YS-Yen. Hed - 600
A1: Yenileme 2026 | B1: 0.3
A4: Satış Hedef Bütçe - Ürün Bazlı
A5: Net Satış M TL | B5: Yeni Satış 2025 | C5: Yenileme 2025 | D5: Total 2025 | E5: YS Büyüme Hedefi | F5: Yeni Satış 2026 | G5: Yenileme 2026 | H5: Total 2026 | I5: 2026 Büyüme | J5: Satış İçindeki Oranı
A6: Enroute | B6: 70053607 | C6: 143242813 | D6: =B6+C6 -> 213296420 | E6: 0.4 | F6: ='2026 Bütçe - 600 (Yıllık)'!I6*1000 -> 1.0508041e+08 | G6: ='2026 Bütçe - 600 (Yıllık)'!M6*1000 -> 1.7787173e+08 | H6: =F6+G6 -> 2.8295214e+08 | I6: =H6/D6-1 -> 0.32656768 | J6: =H6/$H$14 -> 0.15223598
A7: Stokbar | B7: 25018010 | C7: 19223725 | D7: =B7+C7 -> 44241735 | E7: 0.4 | F7: ='2026 Bütçe - 600 (Yıllık)'!I7*1000 -> 41258034 | G7: ='2026 Bütçe - 600 (Yıllık)'!M7*1000 -> 16451099 | H7: =F7+G7 -> 57709133 | I7: =H7/D7-1 -> 0.30440484 | J7: =H7/$H$14 -> 0.031049091
A8: Quest | B8: 13752678 | C8: 13930924 | D8: =B8+C8 -> 27683602 | E8: 2 | F8: ='2026 Bütçe - 600 (Yıllık)'!I8*1000 -> 37527015 | G8: ='2026 Bütçe - 600 (Yıllık)'!M8*1000 -> 22410686 | H8: =F8+G8 -> 59937701 | I8: =H8/D8-1 -> 1.1650976 | J8: =H8/$H$14 -> 0.032248121
A9: ServiceCore | B9: 8415735.8 | C9: 4773940.6 | D9: =B9+C9 -> 13189676 | E9: 1.5 | F9: ='2026 Bütçe - 600 (Yıllık)'!I9*1000 -> 25247208 | G9: ='2026 Bütçe - 600 (Yıllık)'!M9*1000 -> 362971.82 | H9: =F9+G9 -> 25610180 | I9: =H9/D9-1 -> 0.94168372 | J9: =H9/$H$14 -> 0.013778977
A10: Varuna | B10: 3806445 | C10: 2987175 | D10: =B10+C10 -> 6793620 | E10: 0.5 | F10: ='2026 Bütçe - 600 (Yıllık)'!I10*1000 -> 5709667.5 | G10: ='2026 Bütçe - 600 (Yıllık)'!M10*1000 -> 3825506.9 | H10: =F10+G10 -> 9535174.4 | I10: =H10/D10-1 -> 0.40354838 | J10: =H10/$H$14 -> 0.0051301844
A11: Hosting | B11: 690653.09 | C11: 48585095 | D11: =B11+C11 -> 49275748 | E11: 10 | F11: ='2026 Bütçe - 600 (Yıllık)'!I12*1000 -> 7597183 | G11: ='2026 Bütçe - 600 (Yıllık)'!M12*1000 -> 64375251 | H11: =F11+G11 -> 71972434 | I11: =H11/D11-1 -> 0.46060562 | J11: =H11/$H$14 -> 0.038723136
A12: E-Dönüşüm | B12: 25326464 | D12: =B12+C12 -> 25326464 | E12: 2 | F12: ='2026 Bütçe - 600 (Yıllık)'!I11*1000 -> 40000000 | G12: ='2026 Bütçe - 600 (Yıllık)'!M11*'2026 Bütçe - 600 (Yıllık)'!M11 -> 1294488441 | H12: =F12+G12 -> 1334488441 | I12: =H12/D12-1 -> 51.691463 | J12: =H12/$H$14 -> 0.71799125
A13: BFG | B13: 4980743 | D13: 4980743 | E13: 2.3 | F13: ='2026 Bütçe - 600 (Yıllık)'!I13*1000 -> 16436452 | G13: ='2026 Bütçe - 600 (Yıllık)'!M13*1000 -> 0 | H13: =F13+G13 -> 16436452 | I13: =H13/D13-1 -> 2.3 | J13: =H13/$H$14 -> 0.0088432603
A14: Grand Total | B14: =SUM(B6:B13) -> 1.5204434e+08 | C14: =SUM(C6:C13) -> 2.3274367e+08 | D14: =SUM(D6:D13) -> 3.8478801e+08 | F14: =SUM(F6:F13) -> 2.7885597e+08 | G14: =SUM(G6:G13) -> 1.5797857e+09 | H14: =SUM(H6:H13) -> 1.8586417e+09 | I14: =H14/D14-1 -> 3.8303004 | J14: =H14/$H$14 -> 1
A16: Satış Hedef Bütçe - Ürün ve Gelir Tipi Bazında Bazlı (2025-2026) | M16: Yeni Satış | N16: Yenileme | O16: Toplam
A17: Net Satış M TL | B17: Enroute | C17: Stokbar | D17: Quest | E17: ServiceCore | F17: Varuna | G17: Hosting | H17: E-Dönüşüm | I17: BFG | J17: Grand Total | L17: Enroute | M17: 105080.41 | N17: 177871.73 | O17: =SUM(M17:N17) -> 282952.14
A18: Yeni Satış 2025 | B18: 70053607 | C18: 25018010 | D18: 13752678 | E18: 8415735.8 | F18: 3806445 | G18: 690653.09 | H18: 25326464 | I18: 4980743 | J18: =SUM(B18:I18) -> 1.5204434e+08 | L18: Quest | M18: 41258.034 | N18: 16451.099 | O18: =SUM(M18:N18) -> 57709.133
A19: Yenileme 2025 | B19: 143242813 | C19: 19223725 | D19: 13930924 | E19: 4773940.6 | F19: 2987175 | G19: 48585095 | J19: =SUM(B19:I19) -> 2.3274367e+08 | L19: Stokbar | M19: 37527.015 | N19: 22410.686 | O19: =SUM(M19:N19) -> 59937.701
A20: Total 2025 | B20: =(B18+B19) -> 213296420 | C20: =(C18+C19) -> 44241735 | D20: =(D18+D19) -> 27683602 | E20: =(E18+E19) -> 13189676 | F20: =(F18+F19) -> 6793620 | G20: =(G18+G19) -> 49275748 | H20: =(H18+H19) -> 25326464 | I20: =(I18+I19) -> 4980743 | J20: =SUM(B20:I20) -> 3.8478801e+08 | L20: ServiceCore | M20: 25247.208 | N20: 362.97182 | O20: =SUM(M20:N20) -> 25610.18
L21: Varuna | M21: =5709+3826 -> 9535 | N21: 0 | O21: =SUM(M21:N21) -> 9535
A22: YS Büyüme Hedefi | B22: 0.4 | C22: 0.4 | D22: 2 | E22: 1.5 | F22: 0.5 | G22: 10 | H22: 2 | I22: 2.3 | L22: Unidox | M22: 40000 | N22: 35979 | O22: =SUM(M22:N22) -> 75979
A23: Yenileme 2026 Hedefi | B23: 0.3 | C23: =B23 -> 0.3 | D23: =C23 -> 0.3 | E23: =D23 -> 0.3 | F23: =E23 -> 0.3 | G23: 0.331 | H23: =G23 -> 0.331 | I23: =H23 -> 0.331 | L23: Hosting | M23: 7597.183 | N23: 64375.251 | O23: =SUM(M23:N23) -> 71972.434
A24: Yeni Satış 2026 | B24: 1.0508041e+08 | C24: 41258034 | D24: 37527015 | E24: 25247208 | F24: 5709667.5 | G24: 7597183 | H24: 40000000 | I24: 16436452 | J24: =SUM(B24:I24) -> 2.7885597e+08 | L24: BFH | M24: 16436.452 | N24: 0 | O24: =SUM(M24:N24) -> 16436.452
A25: Yenileme 2026 | B25: 1.7787173e+08 | C25: 16451099 | D25: 22410686 | E25: 362971.82 | F25: 3825506.9 | G25: 64375251 | H25: 35979000 | I25: 0 | J25: =SUM(B25:I25) -> 3.2127624e+08 | L25: Toplam | M25: =SUM(M17:M24) -> 282681.3 | N25: =SUM(N17:N24) -> 317450.73 | O25: =SUM(O17:O24) -> 600132.04
A26: Total 2026 | B26: =B24+B25 -> 2.8295214e+08 | C26: =C24+C25 -> 57709133 | D26: =D24+D25 -> 59937701 | E26: =E24+E25 -> 25610180 | F26: =F24+F25 -> 9535174.4 | G26: =G24+G25 -> 71972434 | H26: =H24+H25 -> 75979000 | I26: =I24+I25 -> 16436452 | J26: =SUM(B26:I26) -> 6.0013221e+08
A27: Ciro Oranı | B27: =B26/$J$26 -> 0.471483 | C27: =C26/$J$26 -> 0.0961607 | D27: =D26/$J$26 -> 0.09987416 | E27: =E26/$J$26 -> 0.04267423 | F27: =F26/$J$26 -> 0.015888456 | G27: =G26/$J$26 -> 0.11992763 | H27: =H26/$J$26 -> 0.12660377 | I27: =I26/$J$26 -> 0.027388051
A29: Satış Hedef Bütçe - Ürün-Gelir Tipi ve Müşteri Yöneticisi Bazında (2026) | L29: Satış Hedef Bütçe - Ürün-Gelir Tipi ve Müşteri Yöneticisi Bazında (2026)
A30: Net Satış M TL | B30: Enroute | C30: Stokbar | D30: Quest | E30: ServiceCore | F30: Varuna | G30: Hosting | H30: E-Dönüşüm | I30: BFG | J30: Grand Total | L30: Net Satış M TL | M30: Enroute | N30: Stokbar | O30: Quest | P30: ServiceCore | Q30: Varuna | R30: Hosting | S30: E-Dönüşüm | T30: BFG
A31: Direk+Endirek Satış Toplam | B31: =B35+B59 -> 282952.25 | C31: =C35+C59 -> 57709.245 | D31: =D35+D59 -> 59936.679 | E31: =E35+E59 -> 25610.18 | F31: =F35+F59 -> 9536 | G31: =G35+G59 -> 71971.589 | H31: =H35+H59 -> 75979.392 | I31: =I35+I59 -> 16436 | J31: =J35+J59 -> 600131.34 | L31: Direk+Endirek Satış Toplam | M31: =SUM(M32:M33) -> 1 | N31: =SUM(N32:N33) -> 1 | O31: =SUM(O32:O33) -> 1 | P31: =SUM(P32:P33) -> 1 | Q31: =SUM(Q32:Q33) -> 1 | R31: =SUM(R32:R33) -> 1 | S31: =SUM(S32:S33) -> 1 | T31: =SUM(T32:T33) -> 1
A32: Yeni Satış | B32: =B37+B40+B43+B46+B49+B52+B67+B61+B64+B55 -> 105080 | C32: =C37+C40+C43+C46+C49+C52+C67+C61+C64+C55 -> 41258.082 | D32: =D37+D40+D43+D46+D49+D52+D67+D61+D64+D55 -> 37527 | E32: =E37+E40+E43+E46+E49+E52+E67+E61+E64+E55 -> 25247.208 | F32: =F37+F40+F43+F46+F49+F52+F67+F61+F64+F55 -> 5710 | G32: =G37+G40+G43+G46+G49+G52+G67+G61+G64+G55 -> 7597 | H32: =H37+H40+H43+H46+H49+H52+H67+H61+H64+H55 -> 40000 | I32: =I37+I40+I43+I46+I49+I52+I67+I61+I64+I55 -> 16436 | J32: =SUM(B32:I32) -> 278855.29 | L32: Yeni Satış | M32: =B32/$B$31 -> 0.37137008 | N32: =C32/$C$31 -> 0.71493019 | O32: =D32/$D$31 -> 0.62611076 | P32: =E32/$E$31 -> 0.98582705 | Q32: =F32/$F$31 -> 0.59878356 | R32: =G32/$G$31 -> 0.10555554 | S32: =H32/$H$31 -> 0.52645854 | T32: =I32/$I$31 -> 1
A33: Yenileme | B33: =B38+B41+B44+B47+B50+B53+B68+B62+B65+B56 -> 177872.25 | C33: =C38+C41+C44+C47+C50+C53+C68+C62+C65+C56 -> 16451.163 | D33: =D38+D41+D44+D47+D50+D53+D68+D62+D65+D56 -> 22409.679 | E33: =E38+E41+E44+E47+E50+E53+E68+E62+E65+E56 -> 362.97182 | F33: =F38+F41+F44+F47+F50+F53+F68+F62+F65+F56 -> 3826 | G33: =G38+G41+G44+G47+G50+G53+G68+G62+G65+G56 -> 64374.589 | H33: =H38+H41+H44+H47+H50+H53+H68+H62+H65+H56 -> 35979.392 | I33: =I38+I41+I44+I47+I50+I53+I68+I62+I65+I56 -> 0 | J33: =SUM(B33:I33) -> 321276.05 | L33: Yenileme | M33: =B33/$B$31 -> 0.62862992 | N33: =C33/$C$31 -> 0.28506981 | O33: =D33/$D$31 -> 0.37388924 | P33: =E33/$E$31 -> 0.014172951 | Q33: =F33/$F$31 -> 0.40121644 | R33: =G33/$G$31 -> 0.89444446 | S33: =H33/$H$31 -> 0.47354146 | T33: =I33/$I$31 -> 0
A35: Direk Satış | B35: =B36+B39+B42+B45+B48+B51+B54 -> 264917 | C35: =C36+C39+C42+C45+C48+C51+C54 -> 53391 | D35: =D36+D39+D42+D45+D48+D51+D54 -> 59590.339 | E35: =E36+E39+E42+E45+E48+E51+E54 -> 25610.18 | F35: =F36+F39+F42+F45+F48+F51+F54 -> 9536 | G35: =G36+G39+G42+G45+G48+G51+G54 -> 69326 | H35: =H36+H39+H42+H45+H48+H51+H54 -> 0 | I35: =I36+I39+I42+I45+I48+I51+I54 -> 15936 | J35: =SUM(B35:I35) -> 498306.52 | L35: Direk Satış | M35: =B35/B31 -> 0.93626044 | N35: =C35/C31 -> 0.92517239 | O35: =D35/D31 -> 0.99422156 | P35: =E35/E31 -> 1 | Q35: =F35/F31 -> 1 | R35: =G35/G31 -> 0.9632412 | S35: =H35/H31 -> 0 | T35: =I35/I31 -> 0.96957897
A36: Mülkiye Akdoğaner | B36: =SUM(B37:B38) -> 98500 | C36: =SUM(C37:C38) -> 10000 | D36: =SUM(D37:D38) -> 20400 | E36: =SUM(E37:E38) -> 0 | F36: =SUM(F37:F38) -> 1010 | G36: =SUM(G37:G38) -> 35468 | H36: =SUM(H37:H38) -> 0 | I36: =SUM(I37:I38) -> 4000 | J36: =SUM(J37:J38) -> 169378 | L36: Mülkiye Akdoğaner | M36: =SUM(M37:M38) -> 0.34811527 | N36: =SUM(N37:N38) -> 0.17328246 | O36: =SUM(O37:O38) -> 0.3403592 | P36: =SUM(P37:P38) -> 0 | Q36: =SUM(Q37:Q38) -> 0.10591443 | R36: =SUM(R37:R38) -> 0.49280557 | S36: =SUM(S37:S38) -> 0 | T36: =SUM(T37:T38) -> 0.24336822
A37: Yeni Satış | B37: 35000 | C37: 10000 | D37: 12000 | F37: 1010 | G37: 1000 | I37: 4000 | J37: =SUM(B37:I37) -> 63010 | L37: Yeni Satış | M37: =B37/$B$31 -> 0.12369578 | N37: =C37/$C$31 -> 0.17328246 | O37: =D37/$D$31 -> 0.20021129 | P37: =E37/$E$31 -> 0 | Q37: =F37/$F$31 -> 0.10591443 | R37: =G37/$G$31 -> 0.013894372 | S37: =H37/$H$31 -> 0 | T37: =I37/$I$31 -> 0.24336822
